<?xml version="1.0"?>
<robot xmlns:xacro="http://www.ros.org/wiki/xacro">

<xacro:macro name="dc_motor" params="motor_name parent_link child_link *origin *axis">
  <!-- <xacro:property name="params_yaml" value="$(find gazebo_ros_motors)/params/dc_motor.yaml"/> -->
  <xacro:property name="motor_param" value="${load_yaml(params_yaml)}"/>
  <joint name="${motor_name}" type="continuous">
      <parent link="${parent_link}"/>
      <child link="${child_link}"/>
      <xacro:insert_block name="origin"/>
      <xacro:insert_block name="axis"/>
      <!-- <axis xyz="0 0 1"/> -->
      <dynamics damping="${motor_param['joint_damping']}" friction="${motor_param['joint_friction']}"/>
  </joint>
  <gazebo reference="${motor_name}">
    <provideFeedback>true</provideFeedback>
  </gazebo>
  <gazebo>
    <plugin name="${motor_name}_plugin" filename="libgazebo_ros_dc_motor.so">
      <motor_shaft_joint>${motor_name}</motor_shaft_joint>
      <motor_wrench_frame>${child_link}</motor_wrench_frame>
      <command_topic>${motor_name}/command</command_topic>
      <velocity_topic>${motor_name}/velocity</velocity_topic>
      <encoder_topic>${motor_name}/encoder</encoder_topic>
      <current_topic>${motor_name}/current</current_topic>
      <supply_topic>${motor_name}/supply_voltage</supply_topic>
      <publish_encoder>${motor_param['publish_encoder']}</publish_encoder>
      <publish_velocity>${motor_param['publish_velocity']}</publish_velocity>
      <publish_current>${motor_param['publish_current']}</publish_current>
      <publish_motor_joint_state>${motor_param['publish_motor_joint_state']}</publish_motor_joint_state>
      <update_rate>${motor_param['update_rate']}</update_rate>
      <motor_nominal_voltage>${motor_param['motor_nominal_voltage']}</motor_nominal_voltage>
      <moment_of_inertia>${motor_param['moment_of_inertia']}</moment_of_inertia>
      <armature_damping_ratio>${motor_param['armature_damping_ratio']}</armature_damping_ratio>
      <electromotive_force_constant>${motor_param['electromotive_force_constant']}</electromotive_force_constant>
      <electric_resistance>${motor_param['electric_resistance']}</electric_resistance>
      <electric_inductance>${motor_param['electric_inductance']}</electric_inductance>
      <gear_ratio>${motor_param['gear_ratio']}</gear_ratio>
      <encoder_ppr>${motor_param['encoder_ppr']}</encoder_ppr>
      <rosDebugLevel>Debug</rosDebugLevel>
    </plugin>
  </gazebo>

</xacro:macro>

</robot>
